<?xml version="1.0"?>
<robot xmlns:xacro="http://ros.org/wiki/xacro" name="vt_hands">
  <xacro:include filename="$(find thor_vt_hand_description)/urdf/helper_macros.urdf.xacro.xml"/>
  <!--<xacro:include filename="$(find thor_vt_hand_description)/urdf/vt_finger_tud.urdf.xacro"/>-->
  <xacro:include filename="$(find thor_vt_hand_description)/urdf/vt_finger_tud_single_link.urdf.xacro"/>

  <xacro:macro name="vt_hand_tud_macro" params="parent prefix reflect *origin">
    <xacro:vt_finger_tud_macro prefix="${prefix}_f1" reflect="${reflect*(-1)}"/>
    <xacro:vt_finger_tud_macro prefix="${prefix}_f0" reflect="${reflect}"/>
    <joint name="${prefix}_vt_hand_joint" type="fixed">
      <xacro:insert_block name="origin"/>
      <parent link="${parent}"/>
      <child link="${prefix}_palm"/>
    </joint>
    <!-- link list -->
    <link name="${prefix}_palm">
      <visual>
        <geometry>
          <mesh filename="package://thor_vt_hand_description/meshes/collision/${prefix}_palm.stl"/>
        </geometry>
        <material name="green">
          <color rgba="0 1 0 1"/>
        </material>
      </visual>
      <collision>
        <geometry>
          <mesh filename="package://thor_vt_hand_description/meshes/collision/${prefix}_palm.stl"/>
        </geometry>
        <material name="yellow">
          <color rgba="0 1 1 1"/>
        </material>
      </collision>
      <!-- WARNING: INERTIA NOT CORRECT -->
      <inertial>
        <origin xyz="${reflect*3.44e-03} 6.49e-03 42.12e-03" rpy="0 0 0"/>
        <mass value="0.7"/>
        <inertia ixx="0.1e-04" ixy="0" ixz="0" iyy="0.07e-04" iyz="0" izz="0.1e-04"/>
      </inertial>
    </link>
    <gazebo reference="${prefix}_palm">
      <mu1>1.1</mu1>
      <mu2>1.1</mu2>
      <kp>1000000.0</kp>
      <kd>1.0</kd>
      <maxVel>0.1</maxVel>
      <minDepth>0.00</minDepth>
      <maxContacts>6</maxContacts>
      <!--<material>Gazebo/FlatBlack</material>-->
    </gazebo>
    <!-- end of link list -->
    <!-- joint list -->
    <joint name="${prefix}_f1_j0" type="revolute">
      <parent link="${prefix}_palm"/>
      <child link="${prefix}_f1_link_0"/>
      <axis xyz="1 0 0"/>
      <origin xyz="${reflect*0.036} 0.0361 0.0596" rpy="-1.315 0 0"/>
      <limit lower="0" upper="2.685" effort="10" velocity="10"/>
      <!--<dynamics damping="0.1"/>-->
    </joint>
    <joint name="${prefix}_f0_j0" type="revolute">
      <parent link="${prefix}_palm"/>
      <child link="${prefix}_f0_link_0"/>
      <axis xyz="1 0 0"/>
      <origin xyz="${reflect*-0.0355} 0.0361 0.0596" rpy="-1.315 0 0"/>
      <limit lower="0" upper="2.685" effort="10" velocity="10"/>
      <!--<dynamics damping="0.1"/>-->
    </joint>
    <!-- end of joint list -->
    <!--<gazebo>
        <plugin name="THOR_VT_HandPlugin" filename="libTHOR_VT_HandPlugin.so">
		<prefix>${prefix}</prefix>
        </plugin>

        <kp>1000000.0</kp>
    	<kd>100.0</kd>
   	<mu1>1.5</mu1>
    	<mu2>1.5</mu2>
    	<fdir1>1 0 0</fdir1>
    	<maxVel>1.0</maxVel>
        <minDepth>0.00</minDepth>
        <implicitSpringDamper>1</implicitSpringDamper>
	</gazebo>-->
    <!--Transmissions for gazebo ros control-->
    <xacro:joint_transmission_macro joint_name="${prefix}_f0_j0"/>
    <xacro:joint_transmission_macro joint_name="${prefix}_f1_j0"/>
    <!--gazebo>
    <plugin name="gazebo_ros_control" filename="libgazebo_ros_control.so">
      <robotNamespace>thor_mang</robotNamespace>
      <robotSimType>gazebo_ros_control/VT_Hand_HWSim</robotSimType>
    </plugin>
  </gazebo-->
  </xacro:macro>
</robot>
